<?xml version="1.0"?>
<robot xmlns:xacro="http://www.ros.org/wiki/xacro" name="theclaw">
    <xacro:include filename="$(find theclaw)/urdf/common_properties.xacro"/>
    <xacro:include filename="$(find theclaw)/urdf/theclaw.gazebo.xacro"/>
    <xacro:property name="model_scale" value="0.01 0.01 0.01" />

    <link name="base_footprint"/>

    <joint name="base_joint" type="fixed">
        <parent link="base_footprint"/>
        <child link="base_link"/>
        <origin xyz="0.0 0.0 0.025" rpy=" 0 0 0"/>
    </joint>

    <!-- Base -->

    <link name="base_link">
        <visual>
            <origin rpy="0 0 ${pi/2}"/>
            <geometry>
                <mesh filename="package://theclaw/urdf/meshes/Platform.stl" scale="${model_scale}"/>
            </geometry>
        </visual>
        <collision>
            <origin rpy="0 0 ${pi/2}"/>
            <geometry>
                <cylinder radius="0.060" length="0.02" /> 
            </geometry>
        </collision>
        <xacro:inertial_cylinder mass="0.200" radius="0.060" length="0.02">
            <origin rpy="0 0 ${pi/2}"/>
        </xacro:inertial_cylinder>
    </link>

    <!-- Camera -->

    <link name="camera_link">
        <inertial>
            <mass value="0.01" />
            <origin rpy="0 0 0" xyz="0 0 0" />
            <inertia ixx="0" ixy="0" ixz="0" iyy="0" iyz="0" izz="0" />
        </inertial>
        <visual>
            <origin rpy="0 0 0" xyz="0 0 0" />
            <geometry>
                <box size="0.005 0.05 0.05" />
            </geometry>
        </visual>
    </link>

    <joint name="camera_joint" type="fixed">
        <parent link="base_link" />
        <child link="camera_link" />
        <origin rpy="0 0.2 0" xyz="0.055 0 0.07" />
    </joint>

    <!-- Laser -->

    <link name="laser_base">
        <visual>
            <origin rpy="0 0 0" xyz="0 0 ${0.0186/2}" />
            <geometry>
                <cylinder radius="${0.076/2}" length="0.0186" />
            </geometry>
        </visual>
        <xacro:inertial_cylinder mass="0.050" radius="${0.076/2}" length="0.0186">
            <origin rpy="0 0 0" xyz="0 0 ${0.0186/2}" />
        </xacro:inertial_cylinder>
    </link>

    <link name="laser_head">
        <visual>
            <origin rpy="0 0 0" xyz="0 0 ${(0.041-0.0196)/2}" />
            <geometry>
                <cylinder radius="${0.0725/2}" length="${0.041-0.0196}"/>
            </geometry>
        </visual>
        <xacro:inertial_cylinder mass="0.050" radius="${0.0725/2}" length="${0.041-0.0196}">
            <origin rpy="0 0 0" xyz="0 0 ${0.0186/2}" />
        </xacro:inertial_cylinder>
    </link>

    <joint name="laser_base_joint" type="fixed">
        <parent link="base_link" />
        <child link="laser_base" />
        <origin rpy="0 0 0" xyz="0 0 0.10" />
    </joint>

    <joint name="laser_head_joint" type="fixed">
        <parent link="laser_base" />
        <child link="laser_head" />
        <origin rpy="0 0 0" xyz="0 0 0.0196" />
    </joint>

    <!-- Wheels !-->

    <xacro:macro name="wheel" params="name *origin">
        <link name="${name}_link">
            <visual>
                <origin rpy="0 ${pi/2} 0"/>
                <geometry>
                    <mesh filename="package://theclaw/urdf/meshes/Omniwheel.stl" scale="${model_scale}"/>
                </geometry>
            </visual>
            <collision>
                <origin rpy="0 ${pi/2} 0"/>
                <geometry>
                    <cylinder radius="0.025" length="0.025" /> 
                </geometry>
            </collision>
            <xacro:inertial_cylinder mass="0.020" radius="0.025" length="0.025">
                <origin rpy="0 ${pi/2} 0"/>
            </xacro:inertial_cylinder>
        </link>
        <joint name="${name}_joint" type="continuous">
            <xacro:insert_block name="origin" />
            <parent link="base_link"/>
            <child link="${name}_link"/>
            <limit velocity="10.0" effort="1.0"/>
        </joint>
        <transmission name="${name}_tran">
            <type>transmission_interface/SimpleTransmission</type>
            <joint name="${name}_joint">
                <hardwareInterface>hardware_interface/VelocityJointInterface</hardwareInterface>
            </joint>
            <actuator name="${name}_motor">
                <hardwareInterface>hardware_interface/VelocityJointInterface</hardwareInterface>
                <mechanicalReduction>1</mechanicalReduction>
            </actuator>
        </transmission>
    </xacro:macro>

    <xacro:wheel name="wheel1">
        <origin xyz="0.077647 0 0" rpy="0 0 0"/>
    </xacro:wheel>

    <xacro:wheel name="wheel2">
        <origin xyz="${cos(2*pi/3)*0.077647 - sin(2*pi/3)*0} ${sin(2*pi/3)*0.077647 + cos(2*pi/3)*0} 0" rpy="0 0 ${2*pi/3}"/>
    </xacro:wheel>

    <xacro:wheel name="wheel3">
        <origin xyz="${cos(2*pi/3*2)*0.077647 - sin(2*pi/3*2)*0} ${sin(2*pi/3*2)*0.077647 + cos(2*pi/3*2)*0} 0" rpy="0 0 ${2*pi/3*2}"/>
    </xacro:wheel>
</robot>
