<?xml version="1.0"?>
<robot xmlns:xacro="http://www.ros.org/wiki/xacro" name="theclaw">
    <xacro:include filename="$(find theclaw)/urdf/common_properties.xacro"/>
    <xacro:include filename="$(find theclaw)/urdf/theclaw.gazebo.xacro"/>
    <xacro:property name="model_scale" value="0.01 0.01 0.01" />

    <link name="origin"/>

    <joint name="origin_joint" type="fixed">
        <parent link="origin"/>
        <child link="base_link"/>
        <origin xyz="0.0 0.0 0.0" rpy="0 0 0"/>
    </joint>

    <!-- Base -->

    <xacro:box_link name="base_link" mass="0.050" sx="0.150" sy="0.100" sz="0.005" />

    <!-- Camera -->

    <xacro:box_link name="camera_link" mass="0.001" sx="0.005" sy="0.050" sz="0.050" />

    <joint name="camera_joint" type="fixed">
        <parent link="base_link" />
        <child link="camera_link" />
        <origin rpy="0 0.2 0" xyz="0.055 0 0.07" />
    </joint>

    <!-- Laser -->

    <xacro:cylinder_link name="laser_base_link" mass="0.050" radius="${0.076/2}" length="0.0186" />

    <xacro:cylinder_link name="laser_link" mass="0.050" radius="${0.0725/2}" length="${0.041-0.0196}" />

    <joint name="laser_base_joint" type="fixed">
        <parent link="base_link" />
        <child link="laser_base_link" />
        <origin rpy="0 0 0" xyz="0 0 0.050" />
    </joint>

    <joint name="laser_head_joint" type="fixed">
        <parent link="laser_base_link" />
        <child link="laser_link" />
        <origin rpy="0 0 0" xyz="0 0 ${0.0186/2+(0.041-0.0196)/2}" />
    </joint>

    <!-- Wheels !-->

    <xacro:macro name="wheel" params="name *origin">
        <xacro:cylinder_link name="${name}_link" mass="0.035" radius="0.040" length="0.017" />
        <joint name="${name}_joint" type="continuous">
            <xacro:insert_block name="origin" />
            <parent link="base_link" />
            <child link="${name}_link" />
        </joint>
        <transmission name="${name}_tran">
            <type>transmission_interface/SimpleTransmission</type>
            <joint name="${name}_joint">
                <hardwareInterface>hardware_interface/VelocityJointInterface</hardwareInterface>
            </joint>
            <actuator name="${name}_act">
                <hardwareInterface>hardware_interface/VelocityJointInterface</hardwareInterface>
                <mechanicalReduction>1</mechanicalReduction>
            </actuator>
        </transmission>
    </xacro:macro>

    <xacro:wheel name="wheel_left">
        <origin xyz="0 ${-0.050-0.017/2} 0" rpy="${pi/2} 0 0" />
    </xacro:wheel>

    <xacro:wheel name="wheel_right">
        <origin xyz="0 ${0.050+0.017/2} 0" rpy="${-pi/2} 0 0" />
    </xacro:wheel>

    <!-- Skids -->

    <xacro:macro name="skid" params="name *origin">
        <xacro:sphere_link name="${name}_link1" mass="0.001" radius="0.001" />
        <joint name="${name}_joint1" type="continuous">
            <xacro:insert_block name="origin" />
            <parent link="base_link" />
            <child link="${name}_link1" />
            <axis xyz="1 0 0" />
        </joint>
        <xacro:sphere_link name="${name}_link2" mass="0.001" radius="0.001" />
        <joint name="${name}_joint2" type="continuous">
            <parent link="${name}_link1" />
            <child link="${name}_link2" />
            <axis xyz="0 1 0" />
        </joint>
        <xacro:sphere_link name="${name}_link3" mass="0.010" radius="0.010" />
        <joint name="${name}_joint3" type="continuous">
            <parent link="${name}_link2" />
            <child link="${name}_link3" />
            <axis xyz="0 0 1" />
        </joint>
    </xacro:macro>

    <xacro:skid name="skid_front">
        <origin xyz="0.050 0 ${-0.040+0.010+0.001}" />
    </xacro:skid>

    <xacro:skid name="skid_rear">
        <origin xyz="-0.050 0 ${-0.040+0.010+0.001}" />
    </xacro:skid>
</robot>
